[16-Oct-22 13:33:14 - INFO] - bot - Bot Running..!

Created by 
https://t.me/CodeXBotz
[16-Oct-22 13:48:52 - INFO] - root - Stop signal received (SIGINT). Exiting...
[16-Oct-22 13:48:52 - INFO] - bot - Bot stopped.
[16-Oct-22 13:49:53 - INFO] - bot - Bot Running..!

Created by 
https://t.me/CodeXBotz
[16-Oct-22 13:51:08 - INFO] - root - Stop signal received (SIGINT). Exiting...
[16-Oct-22 13:51:08 - INFO] - bot - Bot stopped.
[16-Oct-22 13:51:23 - INFO] - bot - Bot Running..!

Created by 
https://t.me/CodeXBotz
[16-Oct-22 13:51:31 - INFO] - root - Stop signal received (SIGINT). Exiting...
[16-Oct-22 13:51:31 - INFO] - bot - Bot stopped.
[16-Oct-22 13:51:54 - INFO] - bot - Bot Running..!

Created by 
https://t.me/CodeXBotz
[16-Oct-22 13:57:00 - INFO] - root - Stop signal received (SIGINT). Exiting...
[16-Oct-22 13:57:00 - INFO] - bot - Bot stopped.
[16-Oct-22 13:57:43 - INFO] - bot - Bot Running..!

Created by 
https://t.me/CodeXBotz
[16-Oct-22 14:25:08 - INFO] - root - Stop signal received (SIGINT). Exiting...
[16-Oct-22 14:25:08 - INFO] - bot - Bot stopped.
[16-Oct-22 14:27:51 - INFO] - bot - Bot Running..!

Created by 
https://t.me/CodeXBotz
[18-Oct-22 13:42:48 - ERROR] - pyrogram.dispatcher - Telegram says: [400 MESSAGE_NOT_MODIFIED] - The message was not modified because you tried to edit it using the same content (caused by "messages.EditMessage")
Traceback (most recent call last):
  File "C:\Users\Administrator\AppData\Local\Programs\Python\Python310\lib\site-packages\pyrogram\dispatcher.py", line 240, in handler_worker
    await handler.callback(self.client, *args)
  File "C:\Users\Administrator\OneDrive\Desktop\Bots\Old File-Sharing-Bot\plugins\cbb.py", line 12, in cb_handler
    await query.message.edit_text(
  File "C:\Users\Administrator\AppData\Local\Programs\Python\Python310\lib\site-packages\pyrogram\types\messages_and_media\message.py", line 2777, in edit_text
    return await self._client.edit_message_text(
  File "C:\Users\Administrator\AppData\Local\Programs\Python\Python310\lib\site-packages\pyrogram\methods\messages\edit_message_text.py", line 80, in edit_message_text
    r = await self.invoke(
  File "C:\Users\Administrator\AppData\Local\Programs\Python\Python310\lib\site-packages\pyrogram\methods\advanced\invoke.py", line 77, in invoke
    r = await self.session.invoke(
  File "C:\Users\Administrator\AppData\Local\Programs\Python\Python310\lib\site-packages\pyrogram\session\session.py", line 361, in invoke
    return await self.send(query, timeout=timeout)
  File "C:\Users\Administrator\AppData\Local\Programs\Python\Python310\lib\site-packages\pyrogram\session\session.py", line 331, in send
    RPCError.raise_it(result, type(data))
  File "C:\Users\Administrator\AppData\Local\Programs\Python\Python310\lib\site-packages\pyrogram\errors\rpc_error.py", line 91, in raise_it
    raise getattr(
pyrogram.errors.exceptions.bad_request_400.MessageNotModified: Telegram says: [400 MESSAGE_NOT_MODIFIED] - The message was not modified because you tried to edit it using the same content (caused by "messages.EditMessage")
[21-Oct-22 09:40:29 - ERROR] - pyrogram.dispatcher - Telegram says: [400 MESSAGE_ID_INVALID] - The message id is invalid (caused by "messages.EditMessage")
Traceback (most recent call last):
  File "C:\Users\Administrator\AppData\Local\Programs\Python\Python310\lib\site-packages\pyrogram\dispatcher.py", line 240, in handler_worker
    await handler.callback(self.client, *args)
  File "C:\Users\Administrator\AppData\Local\Programs\Python\Python310\lib\site-packages\pyromod\listen\listen.py", line 93, in resolve_listener
    await self.user_callback(client, message, *args)
  File "C:\Users\Administrator\OneDrive\Desktop\Bots\Old File-Sharing-Bot\plugins\channel_post.py", line 34, in channel_post
    await post_message.edit_reply_markup(reply_markup)
  File "C:\Users\Administrator\AppData\Local\Programs\Python\Python310\lib\site-packages\pyrogram\types\messages_and_media\message.py", line 2913, in edit_reply_markup
    return await self._client.edit_message_reply_markup(
  File "C:\Users\Administrator\AppData\Local\Programs\Python\Python310\lib\site-packages\pyrogram\methods\messages\edit_message_reply_markup.py", line 61, in edit_message_reply_markup
    r = await self.invoke(
  File "C:\Users\Administrator\AppData\Local\Programs\Python\Python310\lib\site-packages\pyrogram\methods\advanced\invoke.py", line 77, in invoke
    r = await self.session.invoke(
  File "C:\Users\Administrator\AppData\Local\Programs\Python\Python310\lib\site-packages\pyrogram\session\session.py", line 361, in invoke
    return await self.send(query, timeout=timeout)
  File "C:\Users\Administrator\AppData\Local\Programs\Python\Python310\lib\site-packages\pyrogram\session\session.py", line 331, in send
    RPCError.raise_it(result, type(data))
  File "C:\Users\Administrator\AppData\Local\Programs\Python\Python310\lib\site-packages\pyrogram\errors\rpc_error.py", line 91, in raise_it
    raise getattr(
pyrogram.errors.exceptions.bad_request_400.MessageIdInvalid: Telegram says: [400 MESSAGE_ID_INVALID] - The message id is invalid (caused by "messages.EditMessage")
[22-Oct-22 06:58:20 - ERROR] - pyrogram.dispatcher - Telegram says: [400 MESSAGE_ID_INVALID] - The message id is invalid (caused by "messages.EditMessage")
Traceback (most recent call last):
  File "C:\Users\Administrator\AppData\Local\Programs\Python\Python310\lib\site-packages\pyrogram\dispatcher.py", line 240, in handler_worker
    await handler.callback(self.client, *args)
  File "C:\Users\Administrator\AppData\Local\Programs\Python\Python310\lib\site-packages\pyromod\listen\listen.py", line 93, in resolve_listener
    await self.user_callback(client, message, *args)
  File "C:\Users\Administrator\OneDrive\Desktop\Bots\Old File-Sharing-Bot\plugins\channel_post.py", line 34, in channel_post
    await post_message.edit_reply_markup(reply_markup)
  File "C:\Users\Administrator\AppData\Local\Programs\Python\Python310\lib\site-packages\pyrogram\types\messages_and_media\message.py", line 2913, in edit_reply_markup
    return await self._client.edit_message_reply_markup(
  File "C:\Users\Administrator\AppData\Local\Programs\Python\Python310\lib\site-packages\pyrogram\methods\messages\edit_message_reply_markup.py", line 61, in edit_message_reply_markup
    r = await self.invoke(
  File "C:\Users\Administrator\AppData\Local\Programs\Python\Python310\lib\site-packages\pyrogram\methods\advanced\invoke.py", line 77, in invoke
    r = await self.session.invoke(
  File "C:\Users\Administrator\AppData\Local\Programs\Python\Python310\lib\site-packages\pyrogram\session\session.py", line 361, in invoke
    return await self.send(query, timeout=timeout)
  File "C:\Users\Administrator\AppData\Local\Programs\Python\Python310\lib\site-packages\pyrogram\session\session.py", line 331, in send
    RPCError.raise_it(result, type(data))
  File "C:\Users\Administrator\AppData\Local\Programs\Python\Python310\lib\site-packages\pyrogram\errors\rpc_error.py", line 91, in raise_it
    raise getattr(
pyrogram.errors.exceptions.bad_request_400.MessageIdInvalid: Telegram says: [400 MESSAGE_ID_INVALID] - The message id is invalid (caused by "messages.EditMessage")
[22-Oct-22 06:58:20 - ERROR] - pyrogram.dispatcher - Telegram says: [400 MESSAGE_ID_INVALID] - The message id is invalid (caused by "messages.EditMessage")
Traceback (most recent call last):
  File "C:\Users\Administrator\AppData\Local\Programs\Python\Python310\lib\site-packages\pyrogram\dispatcher.py", line 240, in handler_worker
    await handler.callback(self.client, *args)
  File "C:\Users\Administrator\AppData\Local\Programs\Python\Python310\lib\site-packages\pyromod\listen\listen.py", line 93, in resolve_listener
    await self.user_callback(client, message, *args)
  File "C:\Users\Administrator\OneDrive\Desktop\Bots\Old File-Sharing-Bot\plugins\channel_post.py", line 34, in channel_post
    await post_message.edit_reply_markup(reply_markup)
  File "C:\Users\Administrator\AppData\Local\Programs\Python\Python310\lib\site-packages\pyrogram\types\messages_and_media\message.py", line 2913, in edit_reply_markup
    return await self._client.edit_message_reply_markup(
  File "C:\Users\Administrator\AppData\Local\Programs\Python\Python310\lib\site-packages\pyrogram\methods\messages\edit_message_reply_markup.py", line 61, in edit_message_reply_markup
    r = await self.invoke(
  File "C:\Users\Administrator\AppData\Local\Programs\Python\Python310\lib\site-packages\pyrogram\methods\advanced\invoke.py", line 77, in invoke
    r = await self.session.invoke(
  File "C:\Users\Administrator\AppData\Local\Programs\Python\Python310\lib\site-packages\pyrogram\session\session.py", line 361, in invoke
    return await self.send(query, timeout=timeout)
  File "C:\Users\Administrator\AppData\Local\Programs\Python\Python310\lib\site-packages\pyrogram\session\session.py", line 331, in send
    RPCError.raise_it(result, type(data))
  File "C:\Users\Administrator\AppData\Local\Programs\Python\Python310\lib\site-packages\pyrogram\errors\rpc_error.py", line 91, in raise_it
    raise getattr(
pyrogram.errors.exceptions.bad_request_400.MessageIdInvalid: Telegram says: [400 MESSAGE_ID_INVALID] - The message id is invalid (caused by "messages.EditMessage")
[22-Oct-22 06:58:20 - WARNING] - pyrogram.session.session - [Bot] Waiting for 4 seconds before continuing (required by "messages.EditMessage")
[22-Oct-22 06:58:21 - WARNING] - pyrogram.session.session - [Bot] Waiting for 3 seconds before continuing (required by "messages.SendMedia")
[22-Oct-22 06:58:21 - WARNING] - pyrogram.session.session - [Bot] Waiting for 3 seconds before continuing (required by "messages.SendMedia")
[22-Oct-22 06:58:24 - WARNING] - pyrogram.session.session - [Bot] Waiting for 3 seconds before continuing (required by "messages.SendMedia")
[22-Oct-22 06:58:24 - WARNING] - pyrogram.session.session - [Bot] Waiting for 3 seconds before continuing (required by "messages.SendMedia")
[22-Oct-22 06:58:25 - ERROR] - pyrogram.dispatcher - Telegram says: [400 MESSAGE_ID_INVALID] - The message id is invalid (caused by "messages.EditMessage")
Traceback (most recent call last):
  File "C:\Users\Administrator\AppData\Local\Programs\Python\Python310\lib\site-packages\pyrogram\dispatcher.py", line 240, in handler_worker
    await handler.callback(self.client, *args)
  File "C:\Users\Administrator\AppData\Local\Programs\Python\Python310\lib\site-packages\pyromod\listen\listen.py", line 93, in resolve_listener
    await self.user_callback(client, message, *args)
  File "C:\Users\Administrator\OneDrive\Desktop\Bots\Old File-Sharing-Bot\plugins\channel_post.py", line 34, in channel_post
    await post_message.edit_reply_markup(reply_markup)
  File "C:\Users\Administrator\AppData\Local\Programs\Python\Python310\lib\site-packages\pyrogram\types\messages_and_media\message.py", line 2913, in edit_reply_markup
    return await self._client.edit_message_reply_markup(
  File "C:\Users\Administrator\AppData\Local\Programs\Python\Python310\lib\site-packages\pyrogram\methods\messages\edit_message_reply_markup.py", line 61, in edit_message_reply_markup
    r = await self.invoke(
  File "C:\Users\Administrator\AppData\Local\Programs\Python\Python310\lib\site-packages\pyrogram\methods\advanced\invoke.py", line 77, in invoke
    r = await self.session.invoke(
  File "C:\Users\Administrator\AppData\Local\Programs\Python\Python310\lib\site-packages\pyrogram\session\session.py", line 361, in invoke
    return await self.send(query, timeout=timeout)
  File "C:\Users\Administrator\AppData\Local\Programs\Python\Python310\lib\site-packages\pyrogram\session\session.py", line 331, in send
    RPCError.raise_it(result, type(data))
  File "C:\Users\Administrator\AppData\Local\Programs\Python\Python310\lib\site-packages\pyrogram\errors\rpc_error.py", line 91, in raise_it
    raise getattr(
pyrogram.errors.exceptions.bad_request_400.MessageIdInvalid: Telegram says: [400 MESSAGE_ID_INVALID] - The message id is invalid (caused by "messages.EditMessage")
[22-Oct-22 06:58:28 - ERROR] - pyrogram.dispatcher - Telegram says: [400 MESSAGE_ID_INVALID] - The message id is invalid (caused by "messages.EditMessage")
Traceback (most recent call last):
  File "C:\Users\Administrator\AppData\Local\Programs\Python\Python310\lib\site-packages\pyrogram\dispatcher.py", line 240, in handler_worker
    await handler.callback(self.client, *args)
  File "C:\Users\Administrator\AppData\Local\Programs\Python\Python310\lib\site-packages\pyromod\listen\listen.py", line 93, in resolve_listener
    await self.user_callback(client, message, *args)
  File "C:\Users\Administrator\OneDrive\Desktop\Bots\Old File-Sharing-Bot\plugins\channel_post.py", line 34, in channel_post
    await post_message.edit_reply_markup(reply_markup)
  File "C:\Users\Administrator\AppData\Local\Programs\Python\Python310\lib\site-packages\pyrogram\types\messages_and_media\message.py", line 2913, in edit_reply_markup
    return await self._client.edit_message_reply_markup(
  File "C:\Users\Administrator\AppData\Local\Programs\Python\Python310\lib\site-packages\pyrogram\methods\messages\edit_message_reply_markup.py", line 61, in edit_message_reply_markup
    r = await self.invoke(
  File "C:\Users\Administrator\AppData\Local\Programs\Python\Python310\lib\site-packages\pyrogram\methods\advanced\invoke.py", line 77, in invoke
    r = await self.session.invoke(
  File "C:\Users\Administrator\AppData\Local\Programs\Python\Python310\lib\site-packages\pyrogram\session\session.py", line 361, in invoke
    return await self.send(query, timeout=timeout)
  File "C:\Users\Administrator\AppData\Local\Programs\Python\Python310\lib\site-packages\pyrogram\session\session.py", line 331, in send
    RPCError.raise_it(result, type(data))
  File "C:\Users\Administrator\AppData\Local\Programs\Python\Python310\lib\site-packages\pyrogram\errors\rpc_error.py", line 91, in raise_it
    raise getattr(
pyrogram.errors.exceptions.bad_request_400.MessageIdInvalid: Telegram says: [400 MESSAGE_ID_INVALID] - The message id is invalid (caused by "messages.EditMessage")
[22-Oct-22 06:58:29 - ERROR] - pyrogram.dispatcher - Telegram says: [400 MESSAGE_ID_INVALID] - The message id is invalid (caused by "messages.EditMessage")
Traceback (most recent call last):
  File "C:\Users\Administrator\AppData\Local\Programs\Python\Python310\lib\site-packages\pyrogram\dispatcher.py", line 240, in handler_worker
    await handler.callback(self.client, *args)
  File "C:\Users\Administrator\AppData\Local\Programs\Python\Python310\lib\site-packages\pyromod\listen\listen.py", line 93, in resolve_listener
    await self.user_callback(client, message, *args)
  File "C:\Users\Administrator\OneDrive\Desktop\Bots\Old File-Sharing-Bot\plugins\channel_post.py", line 34, in channel_post
    await post_message.edit_reply_markup(reply_markup)
  File "C:\Users\Administrator\AppData\Local\Programs\Python\Python310\lib\site-packages\pyrogram\types\messages_and_media\message.py", line 2913, in edit_reply_markup
    return await self._client.edit_message_reply_markup(
  File "C:\Users\Administrator\AppData\Local\Programs\Python\Python310\lib\site-packages\pyrogram\methods\messages\edit_message_reply_markup.py", line 61, in edit_message_reply_markup
    r = await self.invoke(
  File "C:\Users\Administrator\AppData\Local\Programs\Python\Python310\lib\site-packages\pyrogram\methods\advanced\invoke.py", line 77, in invoke
    r = await self.session.invoke(
  File "C:\Users\Administrator\AppData\Local\Programs\Python\Python310\lib\site-packages\pyrogram\session\session.py", line 361, in invoke
    return await self.send(query, timeout=timeout)
  File "C:\Users\Administrator\AppData\Local\Programs\Python\Python310\lib\site-packages\pyrogram\session\session.py", line 331, in send
    RPCError.raise_it(result, type(data))
  File "C:\Users\Administrator\AppData\Local\Programs\Python\Python310\lib\site-packages\pyrogram\errors\rpc_error.py", line 91, in raise_it
    raise getattr(
pyrogram.errors.exceptions.bad_request_400.MessageIdInvalid: Telegram says: [400 MESSAGE_ID_INVALID] - The message id is invalid (caused by "messages.EditMessage")
[22-Oct-22 12:05:41 - ERROR] - pyrogram.dispatcher - Telegram says: [400 MESSAGE_ID_INVALID] - The message id is invalid (caused by "messages.EditMessage")
Traceback (most recent call last):
  File "C:\Users\Administrator\AppData\Local\Programs\Python\Python310\lib\site-packages\pyrogram\dispatcher.py", line 240, in handler_worker
    await handler.callback(self.client, *args)
  File "C:\Users\Administrator\AppData\Local\Programs\Python\Python310\lib\site-packages\pyromod\listen\listen.py", line 93, in resolve_listener
    await self.user_callback(client, message, *args)
  File "C:\Users\Administrator\OneDrive\Desktop\Bots\Old File-Sharing-Bot\plugins\channel_post.py", line 34, in channel_post
    await post_message.edit_reply_markup(reply_markup)
  File "C:\Users\Administrator\AppData\Local\Programs\Python\Python310\lib\site-packages\pyrogram\types\messages_and_media\message.py", line 2913, in edit_reply_markup
    return await self._client.edit_message_reply_markup(
  File "C:\Users\Administrator\AppData\Local\Programs\Python\Python310\lib\site-packages\pyrogram\methods\messages\edit_message_reply_markup.py", line 61, in edit_message_reply_markup
    r = await self.invoke(
  File "C:\Users\Administrator\AppData\Local\Programs\Python\Python310\lib\site-packages\pyrogram\methods\advanced\invoke.py", line 77, in invoke
    r = await self.session.invoke(
  File "C:\Users\Administrator\AppData\Local\Programs\Python\Python310\lib\site-packages\pyrogram\session\session.py", line 361, in invoke
    return await self.send(query, timeout=timeout)
  File "C:\Users\Administrator\AppData\Local\Programs\Python\Python310\lib\site-packages\pyrogram\session\session.py", line 331, in send
    RPCError.raise_it(result, type(data))
  File "C:\Users\Administrator\AppData\Local\Programs\Python\Python310\lib\site-packages\pyrogram\errors\rpc_error.py", line 91, in raise_it
    raise getattr(
pyrogram.errors.exceptions.bad_request_400.MessageIdInvalid: Telegram says: [400 MESSAGE_ID_INVALID] - The message id is invalid (caused by "messages.EditMessage")
[22-Oct-22 12:05:41 - ERROR] - pyrogram.dispatcher - Telegram says: [400 MESSAGE_ID_INVALID] - The message id is invalid (caused by "messages.EditMessage")
Traceback (most recent call last):
  File "C:\Users\Administrator\AppData\Local\Programs\Python\Python310\lib\site-packages\pyrogram\dispatcher.py", line 240, in handler_worker
    await handler.callback(self.client, *args)
  File "C:\Users\Administrator\AppData\Local\Programs\Python\Python310\lib\site-packages\pyromod\listen\listen.py", line 93, in resolve_listener
    await self.user_callback(client, message, *args)
  File "C:\Users\Administrator\OneDrive\Desktop\Bots\Old File-Sharing-Bot\plugins\channel_post.py", line 34, in channel_post
    await post_message.edit_reply_markup(reply_markup)
  File "C:\Users\Administrator\AppData\Local\Programs\Python\Python310\lib\site-packages\pyrogram\types\messages_and_media\message.py", line 2913, in edit_reply_markup
    return await self._client.edit_message_reply_markup(
  File "C:\Users\Administrator\AppData\Local\Programs\Python\Python310\lib\site-packages\pyrogram\methods\messages\edit_message_reply_markup.py", line 61, in edit_message_reply_markup
    r = await self.invoke(
  File "C:\Users\Administrator\AppData\Local\Programs\Python\Python310\lib\site-packages\pyrogram\methods\advanced\invoke.py", line 77, in invoke
    r = await self.session.invoke(
  File "C:\Users\Administrator\AppData\Local\Programs\Python\Python310\lib\site-packages\pyrogram\session\session.py", line 361, in invoke
    return await self.send(query, timeout=timeout)
  File "C:\Users\Administrator\AppData\Local\Programs\Python\Python310\lib\site-packages\pyrogram\session\session.py", line 331, in send
    RPCError.raise_it(result, type(data))
  File "C:\Users\Administrator\AppData\Local\Programs\Python\Python310\lib\site-packages\pyrogram\errors\rpc_error.py", line 91, in raise_it
    raise getattr(
pyrogram.errors.exceptions.bad_request_400.MessageIdInvalid: Telegram says: [400 MESSAGE_ID_INVALID] - The message id is invalid (caused by "messages.EditMessage")
[29-Oct-22 14:42:17 - WARNING] - pyrogram.session.session - [Bot] Waiting for 3 seconds before continuing (required by "messages.EditMessage")
[01-Nov-22 03:08:10 - ERROR] - pyrogram.dispatcher - Telegram says: [403 MESSAGE_DELETE_FORBIDDEN] - You don't have rights to delete messages in this chat, most likely because you are not the author of them (caused by "messages.DeleteMessages")
Traceback (most recent call last):
  File "C:\Users\Administrator\AppData\Local\Programs\Python\Python310\lib\site-packages\pyrogram\dispatcher.py", line 240, in handler_worker
    await handler.callback(self.client, *args)
  File "C:\Users\Administrator\OneDrive\Desktop\Bots\Old File-Sharing-Bot\plugins\cbb.py", line 24, in cb_handler
    await query.message.delete()
  File "C:\Users\Administrator\AppData\Local\Programs\Python\Python310\lib\site-packages\pyrogram\types\messages_and_media\message.py", line 3186, in delete
    return await self._client.delete_messages(
  File "C:\Users\Administrator\AppData\Local\Programs\Python\Python310\lib\site-packages\pyrogram\methods\messages\delete_messages.py", line 75, in delete_messages
    r = await self.invoke(
  File "C:\Users\Administrator\AppData\Local\Programs\Python\Python310\lib\site-packages\pyrogram\methods\advanced\invoke.py", line 77, in invoke
    r = await self.session.invoke(
  File "C:\Users\Administrator\AppData\Local\Programs\Python\Python310\lib\site-packages\pyrogram\session\session.py", line 361, in invoke
    return await self.send(query, timeout=timeout)
  File "C:\Users\Administrator\AppData\Local\Programs\Python\Python310\lib\site-packages\pyrogram\session\session.py", line 331, in send
    RPCError.raise_it(result, type(data))
  File "C:\Users\Administrator\AppData\Local\Programs\Python\Python310\lib\site-packages\pyrogram\errors\rpc_error.py", line 91, in raise_it
    raise getattr(
pyrogram.errors.exceptions.forbidden_403.MessageDeleteForbidden: Telegram says: [403 MESSAGE_DELETE_FORBIDDEN] - You don't have rights to delete messages in this chat, most likely because you are not the author of them (caused by "messages.DeleteMessages")
[01-Nov-22 03:08:11 - ERROR] - pyrogram.dispatcher - Telegram says: [403 MESSAGE_DELETE_FORBIDDEN] - You don't have rights to delete messages in this chat, most likely because you are not the author of them (caused by "messages.DeleteMessages")
Traceback (most recent call last):
  File "C:\Users\Administrator\AppData\Local\Programs\Python\Python310\lib\site-packages\pyrogram\dispatcher.py", line 240, in handler_worker
    await handler.callback(self.client, *args)
  File "C:\Users\Administrator\OneDrive\Desktop\Bots\Old File-Sharing-Bot\plugins\cbb.py", line 24, in cb_handler
    await query.message.delete()
  File "C:\Users\Administrator\AppData\Local\Programs\Python\Python310\lib\site-packages\pyrogram\types\messages_and_media\message.py", line 3186, in delete
    return await self._client.delete_messages(
  File "C:\Users\Administrator\AppData\Local\Programs\Python\Python310\lib\site-packages\pyrogram\methods\messages\delete_messages.py", line 75, in delete_messages
    r = await self.invoke(
  File "C:\Users\Administrator\AppData\Local\Programs\Python\Python310\lib\site-packages\pyrogram\methods\advanced\invoke.py", line 77, in invoke
    r = await self.session.invoke(
  File "C:\Users\Administrator\AppData\Local\Programs\Python\Python310\lib\site-packages\pyrogram\session\session.py", line 361, in invoke
    return await self.send(query, timeout=timeout)
  File "C:\Users\Administrator\AppData\Local\Programs\Python\Python310\lib\site-packages\pyrogram\session\session.py", line 331, in send
    RPCError.raise_it(result, type(data))
  File "C:\Users\Administrator\AppData\Local\Programs\Python\Python310\lib\site-packages\pyrogram\errors\rpc_error.py", line 91, in raise_it
    raise getattr(
pyrogram.errors.exceptions.forbidden_403.MessageDeleteForbidden: Telegram says: [403 MESSAGE_DELETE_FORBIDDEN] - You don't have rights to delete messages in this chat, most likely because you are not the author of them (caused by "messages.DeleteMessages")
[01-Nov-22 03:08:11 - ERROR] - pyrogram.dispatcher - Telegram says: [403 MESSAGE_DELETE_FORBIDDEN] - You don't have rights to delete messages in this chat, most likely because you are not the author of them (caused by "messages.DeleteMessages")
Traceback (most recent call last):
  File "C:\Users\Administrator\AppData\Local\Programs\Python\Python310\lib\site-packages\pyrogram\dispatcher.py", line 240, in handler_worker
    await handler.callback(self.client, *args)
  File "C:\Users\Administrator\OneDrive\Desktop\Bots\Old File-Sharing-Bot\plugins\cbb.py", line 24, in cb_handler
    await query.message.delete()
  File "C:\Users\Administrator\AppData\Local\Programs\Python\Python310\lib\site-packages\pyrogram\types\messages_and_media\message.py", line 3186, in delete
    return await self._client.delete_messages(
  File "C:\Users\Administrator\AppData\Local\Programs\Python\Python310\lib\site-packages\pyrogram\methods\messages\delete_messages.py", line 75, in delete_messages
    r = await self.invoke(
  File "C:\Users\Administrator\AppData\Local\Programs\Python\Python310\lib\site-packages\pyrogram\methods\advanced\invoke.py", line 77, in invoke
    r = await self.session.invoke(
  File "C:\Users\Administrator\AppData\Local\Programs\Python\Python310\lib\site-packages\pyrogram\session\session.py", line 361, in invoke
    return await self.send(query, timeout=timeout)
  File "C:\Users\Administrator\AppData\Local\Programs\Python\Python310\lib\site-packages\pyrogram\session\session.py", line 331, in send
    RPCError.raise_it(result, type(data))
  File "C:\Users\Administrator\AppData\Local\Programs\Python\Python310\lib\site-packages\pyrogram\errors\rpc_error.py", line 91, in raise_it
    raise getattr(
pyrogram.errors.exceptions.forbidden_403.MessageDeleteForbidden: Telegram says: [403 MESSAGE_DELETE_FORBIDDEN] - You don't have rights to delete messages in this chat, most likely because you are not the author of them (caused by "messages.DeleteMessages")
[01-Nov-22 03:08:11 - ERROR] - pyrogram.dispatcher - Telegram says: [400 MESSAGE_NOT_MODIFIED] - The message was not modified because you tried to edit it using the same content (caused by "messages.EditMessage")
Traceback (most recent call last):
  File "C:\Users\Administrator\AppData\Local\Programs\Python\Python310\lib\site-packages\pyrogram\dispatcher.py", line 240, in handler_worker
    await handler.callback(self.client, *args)
  File "C:\Users\Administrator\OneDrive\Desktop\Bots\Old File-Sharing-Bot\plugins\cbb.py", line 12, in cb_handler
    await query.message.edit_text(
  File "C:\Users\Administrator\AppData\Local\Programs\Python\Python310\lib\site-packages\pyrogram\types\messages_and_media\message.py", line 2777, in edit_text
    return await self._client.edit_message_text(
  File "C:\Users\Administrator\AppData\Local\Programs\Python\Python310\lib\site-packages\pyrogram\methods\messages\edit_message_text.py", line 80, in edit_message_text
    r = await self.invoke(
  File "C:\Users\Administrator\AppData\Local\Programs\Python\Python310\lib\site-packages\pyrogram\methods\advanced\invoke.py", line 77, in invoke
    r = await self.session.invoke(
  File "C:\Users\Administrator\AppData\Local\Programs\Python\Python310\lib\site-packages\pyrogram\session\session.py", line 361, in invoke
    return await self.send(query, timeout=timeout)
  File "C:\Users\Administrator\AppData\Local\Programs\Python\Python310\lib\site-packages\pyrogram\session\session.py", line 331, in send
    RPCError.raise_it(result, type(data))
  File "C:\Users\Administrator\AppData\Local\Programs\Python\Python310\lib\site-packages\pyrogram\errors\rpc_error.py", line 91, in raise_it
    raise getattr(
pyrogram.errors.exceptions.bad_request_400.MessageNotModified: Telegram says: [400 MESSAGE_NOT_MODIFIED] - The message was not modified because you tried to edit it using the same content (caused by "messages.EditMessage")
[02-Nov-22 04:31:08 - INFO] - root - Stop signal received (SIGINT). Exiting...
[02-Nov-22 04:31:08 - INFO] - bot - Bot stopped.
[02-Nov-22 05:34:28 - INFO] - bot - Bot Running..!

Created by 
https://t.me/CodeXBotz
[05-Nov-22 04:43:32 - INFO] - root - Stop signal received (SIGINT). Exiting...
[05-Nov-22 04:43:33 - INFO] - bot - Bot stopped.
[05-Nov-22 04:48:36 - INFO] - bot - Bot Running..!

Created by 
https://t.me/CodeXBotz
[16-Nov-22 13:59:43 - ERROR] - pyrogram.dispatcher - Telegram says: [403 MESSAGE_DELETE_FORBIDDEN] - You don't have rights to delete messages in this chat, most likely because you are not the author of them (caused by "messages.DeleteMessages")
Traceback (most recent call last):
  File "C:\Users\Administrator\AppData\Local\Programs\Python\Python310\lib\site-packages\pyrogram\dispatcher.py", line 240, in handler_worker
    await handler.callback(self.client, *args)
  File "C:\Users\Administrator\OneDrive\Desktop\Bots\Old File-Sharing-Bot\plugins\cbb.py", line 24, in cb_handler
    await query.message.delete()
  File "C:\Users\Administrator\AppData\Local\Programs\Python\Python310\lib\site-packages\pyrogram\types\messages_and_media\message.py", line 3186, in delete
    return await self._client.delete_messages(
  File "C:\Users\Administrator\AppData\Local\Programs\Python\Python310\lib\site-packages\pyrogram\methods\messages\delete_messages.py", line 75, in delete_messages
    r = await self.invoke(
  File "C:\Users\Administrator\AppData\Local\Programs\Python\Python310\lib\site-packages\pyrogram\methods\advanced\invoke.py", line 77, in invoke
    r = await self.session.invoke(
  File "C:\Users\Administrator\AppData\Local\Programs\Python\Python310\lib\site-packages\pyrogram\session\session.py", line 361, in invoke
    return await self.send(query, timeout=timeout)
  File "C:\Users\Administrator\AppData\Local\Programs\Python\Python310\lib\site-packages\pyrogram\session\session.py", line 331, in send
    RPCError.raise_it(result, type(data))
  File "C:\Users\Administrator\AppData\Local\Programs\Python\Python310\lib\site-packages\pyrogram\errors\rpc_error.py", line 91, in raise_it
    raise getattr(
pyrogram.errors.exceptions.forbidden_403.MessageDeleteForbidden: Telegram says: [403 MESSAGE_DELETE_FORBIDDEN] - You don't have rights to delete messages in this chat, most likely because you are not the author of them (caused by "messages.DeleteMessages")
